version: '3'
services:
  api-gateway:
    build: ./api_gateway
    ports:
      - "5010:5000"
    volumes:
      - './api_gateway:/code'
    environment:
      PYTHONUNBUFFERED: 'true'
    networks:
      social_net:
        ipv4_address: 172.28.1.1

  stories:
    build: ./stories_service
    ports:
      - "5001:5000"
    volumes:
      - './stories_service:/code'
    environment:
      PYTHONUNBUFFERED: 'true'
    networks:
      social_net:
        ipv4_address: 172.28.1.2

  users:
    build: ./users_service
    ports:
      - "5002:5000"
    volumes:
      - './users_service:/code'
    environment:
      PYTHONUNBUFFERED: 'true'
    networks:
      social_net:
        ipv4_address: 172.28.1.3

  dice:
    build: ./DiceManagement
    depends_on:
      - mongodb
    links:
      - mongodb    
    ports:
      - "5003:5000"
    volumes:
      - './DiceManagement:/code'
    environment:
      WAIT_HOSTS: mongodb:27017
      PYTHONUNBUFFERED: 'true'
    restart: on-failure
    networks:
      social_net:
        ipv4_address: 172.28.1.4

  profiling:
      build: ./socialdice_profiling
      ports:
        - "5004:5000"
      volumes:
        - './socialdice_profiling:/code'
      environment:
        PYTHONUNBUFFERED: 'true'
      networks:
        social_net:
          ipv4_address: 172.28.1.5

  reactions:
    build: ./reactions_service
    ports:
      - "5005:5000"
    volumes:
      - './reactions_service:/code'
    environment:
      PYTHONUNBUFFERED: 'true'
    networks:
      social_net:
        ipv4_address: 172.28.1.6

  redis-reactions:
    image: "redis:alpine"
    ports:
      - "6379:6379"
    networks:
      social_net:
        ipv4_address: 172.28.1.7

  redis-profiling:
    image: "redis:alpine"
    ports:
      - "6380:6379"
    networks:
      social_net:
        ipv4_address: 172.28.1.8

  celery-reactions:
    build: ./reactions_service
    command: celery worker -l error -E -A service.background
    volumes: # for bind volume
      - './reactions_service:/code'
    networks:
      social_net:
        ipv4_address: 172.28.1.9

  celery-profiling:
    build: ./socialdice_profiling
    command: celery worker -l error -E -A stats_service.background
    volumes: 
      - './socialdice_profiling:/code'
    networks:
      social_net:
        ipv4_address: 172.28.1.10

  mongodb:
    image: "mongo"
    container_name: "mongodb"
    environment:
      - MONGO_INITDB_DATABASE=DiceDB
    ports:
      - "27017:27017"
    command: mongod --bind_ip=172.28.1.11
    healthcheck:
      test: ["CMD", "curl", "-f", "http://172.28.1.11:27017"]
      interval: 30s
      timeout: 10s
      retries: 5
    networks:
      social_net:
        ipv4_address: 172.28.1.11

networks:    
  social_net:
    ipam:
      driver: default            
      config:                
      - subnet: 172.28.0.0/16